Workbook

Sheet 销售物业-海沧A璞盛
A1: 一、工程进度： | C1: =+[1]关键节点!G2 -> 竣备 | D1: =+[1]关键节点!H2 -> 交付/开业 | E1: =+[1]关键节点!I2 -> 交付 （合同约定）
C2: =+[1]关键节点!G8 -> 46265 | D2: =+[1]关键节点!H8 -> 住宅：2027/4/30 商业：2027/5/1 | E2: =+[1]关键节点!I8 -> 46568
A3: 二、销售情况 | P3: W | S3: X | V3: Y | Y3: Z | AB3: AA | AE3: AB
A4: 海沧璞盛 | D4: 合计 | G4: 2025年及以前已实现 | J4: 2026年1-3月 | M4: 截止26年3月待售 | P4: 2026年预计 | S4: 2027年预计 | V4: 2028年预计 | Y4: 2029年预计 | AB4: 2030年预计 | AE4: 2031年及以后预计
D5: 合计 | E5: 一期 | F5: 二期 | G5: 合计 | H5: 一期 | I5: 二期 | P5: 合计 | Q5: 一期 | R5: 二期 | S5: 合计 | T5: 一期 | U5: 二期 | V5: 合计 | W5: 一期 | X5: 二期 | Y5: 合计 | Z5: 一期 | AA5: 二期 | AB5: 合计 | AC5: 一期 | AD5: 二期 | AE5: 合计 | AF5: 一期 | AG5: 二期
A6: 签约 | C6: 合计 | D6: =SUM(D8:D11) -> 42.089468 | E6: =SUM(E8:E11) -> 33.553411 | F6: =SUM(F8:F11) -> 8.5360571 | G6: =SUM(G8:G11) -> 29.534337 | H6: =SUM(H8:H11) -> 22.108743 | I6: =SUM(I8:I11) -> 7.4255942 | J6: =SUM(J8:J11) -> 0 | K6: =SUM(K8:K11) -> 0 | ... AG6: =SUM(AG8:AG11) -> 0
C7: 住宅 | D7: =SUM(D8:D9) -> 39.628221 | E7: =SUM(E8:E9) -> 31.431942 | F7: =SUM(F8:F9) -> 8.196279 | G7: =SUM(G8:G9) -> 29.250237 | H7: =SUM(H8:H9) -> 21.892443 | I7: =SUM(I8:I9) -> 7.3577942 | P7: =SUM(P8:P9) -> 6.6912545 | Q7: =SUM(Q8:Q9) -> 5.8527696 | R7: =SUM(R8:R9) -> 0.83848488 | S7: =SUM(S8:S9) -> 3.6867291 | T7: =SUM(T8:T9) -> 3.6867291 | U7: =SUM(U8:U9) -> 0 | V7: =SUM(V8:V9) -> 0 | W7: =SUM(W8:W9) -> 0 | ... AG7: =SUM(AG8:AG9) -> 0
C8: 其中：普宅 | D8: =SUM(E8:F8) -> 30.637492 | E8: =SUM(H8,Q8,T8,W8,Z8,AC8,AF8) -> 22.441213 | F8: =SUM(I8,R8,U8,X8,AA8,AD8,AG8) -> 8.196279 | G8: =SUM(H8:I8) -> 29.250237 | H8: =(SUMIFS('[2]1.1地产销售计划表'!N:N,'[2]1.1地产销售计划表'!B:B,"海沧中心璞盛项目（一期）",'[2]1.1地产销售计划表'!G:G,"住宅-精装普宅",'[2]1.1地产销售计划表'!H:H,"签约(元）")+SUMIFS('[2]1.1地产销售计划表'!V:V,'[2]1.1地产销售计划表'!B:B,"海沧中心璞盛项目（一期）",'[2]1.1地产销售计划表'!G:G,"住宅-精装普宅",'[2]1.1地产销售计划表'!H:H,"签约(元）"))/100000000 -> 21.892443 | I8: =(SUMIFS('[2]1.1地产销售计划表'!N:N,'[2]1.1地产销售计划表'!B:B,"海沧中心璞盛项目（二期）",'[2]1.1地产销售计划表'!G:G,"住宅-精装普宅",'[2]1.1地产销售计划表'!H:H,"签约(元）")+SUMIFS('[2]1.1地产销售计划表'!V:V,'[2]1.1地产销售计划表'!B:B,"海沧中心璞盛项目（二期）",'[2]1.1地产销售计划表'!G:G,"住宅-精装普宅",'[2]1.1地产销售计划表'!H:H,"签约(元）"))/100000000 -> 7.3577942 | P8: =SUM(Q8:R8) -> 1.3872545 | Q8: =SUMIFS('[2]1.1地产销售计划表'!W:W,'[2]1.1地产销售计划表'!B:B,"海沧中心璞盛项目（一期）",'[2]1.1地产销售计划表'!G:G,"住宅-精装普宅",'[2]1.1地产销售计划表'!H:H,"签约(元）")/100000000 -> 0.54876958 | R8: =SUMIFS('[2]1.1地产销售计划表'!W:W,'[2]1.1地产销售计划表'!B:B,"海沧中心璞盛项目（二期）",'[2]1.1地产销售计划表'!G:G,"住宅-精装普宅",'[2]1.1地产销售计划表'!H:H,"签约(元）")/100000000 -> 0.83848488 | S8: =SUM(T8:U8) -> 0 | T8: =SUMIFS('[2]1.1地产销售计划表'!X:X,'[2]1.1地产销售计划表'!B:B,"海沧中心璞盛项目（一期）",'[2]1.1地产销售计划表'!G:G,"住宅-精装普宅",'[2]1.1地产销售计划表'!H:H,"签约(元）")/100000000 -> 0 | U8: =SUMIFS('[2]1.1地产销售计划表'!X:X,'[2]1.1地产销售计划表'!B:B,"海沧中心璞盛项目（二期）",'[2]1.1地产销售计划表'!G:G,"住宅-精装普宅",'[2]1.1地产销售计划表'!H:H,"签约(元）")/100000000 -> 0 | V8: =SUM(W8:X8) -> 0 | W8: =SUMIFS('[2]1.1地产销售计划表'!Y:Y,'[2]1.1地产销售计划表'!B:B,"海沧中心璞盛项目（一期）",'[2]1.1地产销售计划表'!G:G,"住宅-精装普宅",'[2]1.1地产销售计划表'!H:H,"签约(元）")/100000000 -> 0 | X8: =SUMIFS('[2]1.1地产销售计划表'!Y:Y,'[2]1.1地产销售计划表'!B:B,"海沧中心璞盛项目（二期）",'[2]1.1地产销售计划表'!G:G,"住宅-精装普宅",'[2]1.1地产销售计划表'!H:H,"签约(元）")/100000000 -> 0 | Y8: =SUM(Z8:AA8) -> 0 | Z8: =SUMIFS('[2]1.1地产销售计划表'!Z:Z,'[2]1.1地产销售计划表'!B:B,"海沧中心璞盛项目（一期）",'[2]1.1地产销售计划表'!G:G,"住宅-精装普宅",'[2]1.1地产销售计划表'!H:H,"签约(元）")/100000000 -> 0 | AA8: =SUMIFS('[2]1.1地产销售计划表'!Z:Z,'[2]1.1地产销售计划表'!B:B,"海沧中心璞盛项目（二期）",'[2]1.1地产销售计划表'!G:G,"住宅-精装普宅",'[2]1.1地产销售计划表'!H:H,"签约(元）")/100000000 -> 0 | AB8: =SUM(AC8:AD8) -> 0 | AC8: =SUMIFS('[2]1.1地产销售计划表'!AA:AA,'[2]1.1地产销售计划表'!B:B,"海沧中心璞盛项目（一期）",'[2]1.1地产销售计划表'!G:G,"住宅-精装普宅",'[2]1.1地产销售计划表'!H:H,"签约(元）")/100000000 -> 0 | AD8: =SUMIFS('[2]1.1地产销售计划表'!AA:AA,'[2]1.1地产销售计划表'!B:B,"海沧中心璞盛项目（二期）",'[2]1.1地产销售计划表'!G:G,"住宅-精装普宅",'[2]1.1地产销售计划表'!H:H,"签约(元）")/100000000 -> 0 | AE8: =SUM(AF8:AG8) -> 0 | AF8: =SUMIFS('[2]1.1地产销售计划表'!AB:AB,'[2]1.1地产销售计划表'!B:B,"海沧中心璞盛项目（一期）",'[2]1.1地产销售计划表'!G:G,"住宅-精装普宅",'[2]1.1地产销售计划表'!H:H,"签约(元）")/100000000 -> 0 | AG8: =SUMIFS('[2]1.1地产销售计划表'!AB:AB,'[2]1.1地产销售计划表'!B:B,"海沧中心璞盛项目（二期）",'[2]1.1地产销售计划表'!G:G,"住宅-精装普宅",'[2]1.1地产销售计划表'!H:H,"签约(元）")/100000000 -> 0
C9: 非普宅 | D9: =SUM(E9:F9) -> 8.9907291 | E9: =SUM(H9,Q9,T9,W9,Z9,AC9,AF9) -> 8.9907291 | F9: =SUM(I9,R9,U9,X9,AA9,AD9,AG9) -> 0 | G9: =SUM(H9:I9) -> 0 | H9: =(SUMIFS('[2]1.1地产销售计划表'!N:N,'[2]1.1地产销售计划表'!B:B,"海沧中心璞盛项目（一期）",'[2]1.1地产销售计划表'!G:G,"住宅-精装非普宅",'[2]1.1地产销售计划表'!H:H,"签约(元）")+SUMIFS('[2]1.1地产销售计划表'!V:V,'[2]1.1地产销售计划表'!B:B,"海沧中心璞盛项目（一期）",'[2]1.1地产销售计划表'!G:G,"住宅-精装非普宅",'[2]1.1地产销售计划表'!H:H,"签约(元）"))/100000000 -> 0 | I9: =(SUMIFS('[2]1.1地产销售计划表'!N:N,'[2]1.1地产销售计划表'!B:B,"海沧中心璞盛项目（二期）",'[2]1.1地产销售计划表'!G:G,"住宅-精装非普宅",'[2]1.1地产销售计划表'!H:H,"签约(元）")+SUMIFS('[2]1.1地产销售计划表'!V:V,'[2]1.1地产销售计划表'!B:B,"海沧中心璞盛项目（二期）",'[2]1.1地产销售计划表'!G:G,"住宅-精装非普宅",'[2]1.1地产销售计划表'!H:H,"签约(元）"))/100000000 -> 0 | P9: =SUM(Q9:R9) -> 5.304 | Q9: =SUMIFS('[2]1.1地产销售计划表'!W:W,'[2]1.1地产销售计划表'!B:B,"海沧中心璞盛项目（一期）",'[2]1.1地产销售计划表'!G:G,"住宅-精装非普宅",'[2]1.1地产销售计划表'!H:H,"签约(元）")/100000000 -> 5.304 | R9: =SUMIFS('[2]1.1地产销售计划表'!W:W,'[2]1.1地产销售计划表'!B:B,"海沧中心璞盛项目（二期）",'[2]1.1地产销售计划表'!G:G,"住宅-精装非普宅",'[2]1.1地产销售计划表'!H:H,"签约(元）")/100000000 -> 0 | S9: =SUM(T9:U9) -> 3.6867291 | T9: =SUMIFS('[2]1.1地产销售计划表'!X:X,'[2]1.1地产销售计划表'!B:B,"海沧中心璞盛项目（一期）",'[2]1.1地产销售计划表'!G:G,"住宅-精装非普宅",'[2]1.1地产销售计划表'!H:H,"签约(元）")/100000000 -> 3.6867291 | U9: =SUMIFS('[2]1.1地产销售计划表'!X:X,'[2]1.1地产销售计划表'!B:B,"海沧中心璞盛项目（二期）",'[2]1.1地产销售计划表'!G:G,"住宅-精装非普宅",'[2]1.1地产销售计划表'!H:H,"签约(元）")/100000000 -> 0 | V9: =SUM(W9:X9) -> 0 | W9: =SUMIFS('[2]1.1地产销售计划表'!Y:Y,'[2]1.1地产销售计划表'!B:B,"海沧中心璞盛项目（一期）",'[2]1.1地产销售计划表'!G:G,"住宅-精装非普宅",'[2]1.1地产销售计划表'!H:H,"签约(元）")/100000000 -> 0 | X9: =SUMIFS('[2]1.1地产销售计划表'!Y:Y,'[2]1.1地产销售计划表'!B:B,"海沧中心璞盛项目（二期）",'[2]1.1地产销售计划表'!G:G,"住宅-精装非普宅",'[2]1.1地产销售计划表'!H:H,"签约(元）")/100000000 -> 0 | Y9: =SUM(Z9:AA9) -> 0 | Z9: =SUMIFS('[2]1.1地产销售计划表'!Z:Z,'[2]1.1地产销售计划表'!B:B,"海沧中心璞盛项目（一期）",'[2]1.1地产销售计划表'!G:G,"住宅-精装非普宅",'[2]1.1地产销售计划表'!H:H,"签约(元）")/100000000 -> 0 | AA9: =SUMIFS('[2]1.1地产销售计划表'!Z:Z,'[2]1.1地产销售计划表'!B:B,"海沧中心璞盛项目（二期）",'[2]1.1地产销售计划表'!G:G,"住宅-精装非普宅",'[2]1.1地产销售计划表'!H:H,"签约(元）")/100000000 -> 0 | AB9: =SUM(AC9:AD9) -> 0 | AC9: =SUMIFS('[2]1.1地产销售计划表'!AA:AA,'[2]1.1地产销售计划表'!B:B,"海沧中心璞盛项目（一期）",'[2]1.1地产销售计划表'!G:G,"住宅-精装非普宅",'[2]1.1地产销售计划表'!H:H,"签约(元）")/100000000 -> 0 | AD9: =SUMIFS('[2]1.1地产销售计划表'!AA:AA,'[2]1.1地产销售计划表'!B:B,"海沧中心璞盛项目（二期）",'[2]1.1地产销售计划表'!G:G,"住宅-精装非普宅",'[2]1.1地产销售计划表'!H:H,"签约(元）")/100000000 -> 0 | AE9: =SUM(AF9:AG9) -> 0 | AF9: =SUMIFS('[2]1.1地产销售计划表'!AB:AB,'[2]1.1地产销售计划表'!B:B,"海沧中心璞盛项目（一期）",'[2]1.1地产销售计划表'!G:G,"住宅-精装非普宅",'[2]1.1地产销售计划表'!H:H,"签约(元）")/100000000 -> 0 | AG9: =SUMIFS('[2]1.1地产销售计划表'!AB:AB,'[2]1.1地产销售计划表'!B:B,"海沧中心璞盛项目（二期）",'[2]1.1地产销售计划表'!G:G,"住宅-精装非普宅",'[2]1.1地产销售计划表'!H:H,"签约(元）")/100000000 -> 0
C10: 商业 | D10: =SUM(E10:F10) -> 0.710247 | E10: =SUM(H10,Q10,T10,W10,Z10,AC10,AF10) -> 0.628269 | F10: =SUM(I10,R10,U10,X10,AA10,AD10,AG10) -> 0.081978 | G10: =SUM(H10:I10) -> 0 | H10: =(SUMIFS('[2]1.1地产销售计划表'!N:N,'[2]1.1地产销售计划表'!B:B,"海沧中心璞盛项目（一期）",'[2]1.1地产销售计划表'!G:G,"商业",'[2]1.1地产销售计划表'!H:H,"签约(元）")+SUMIFS('[2]1.1地产销售计划表'!V:V,'[2]1.1地产销售计划表'!B:B,"海沧中心璞盛项目（一期）",'[2]1.1地产销售计划表'!G:G,"商业",'[2]1.1地产销售计划表'!H:H,"签约(元）"))/100000000 -> 0 | I10: =(SUMIFS('[2]1.1地产销售计划表'!N:N,'[2]1.1地产销售计划表'!B:B,"海沧中心璞盛项目（二期）",'[2]1.1地产销售计划表'!G:G,"商业",'[2]1.1地产销售计划表'!H:H,"签约(元）")+SUMIFS('[2]1.1地产销售计划表'!V:V,'[2]1.1地产销售计划表'!B:B,"海沧中心璞盛项目（二期）",'[2]1.1地产销售计划表'!G:G,"商业",'[2]1.1地产销售计划表'!H:H,"签约(元）"))/100000000 -> 0 | P10: =SUM(Q10:R10) -> 0 | Q10: =SUMIFS('[2]1.1地产销售计划表'!W:W,'[2]1.1地产销售计划表'!B:B,"海沧中心璞盛项目（一期）",'[2]1.1地产销售计划表'!G:G,"商业",'[2]1.1地产销售计划表'!H:H,"签约(元）")/100000000 -> 0 | R10: =SUMIFS('[2]1.1地产销售计划表'!W:W,'[2]1.1地产销售计划表'!B:B,"海沧中心璞盛项目（二期）",'[2]1.1地产销售计划表'!G:G,"商业",'[2]1.1地产销售计划表'!H:H,"签约(元）")/100000000 -> 0 | S10: =SUM(T10:U10) -> 0 | T10: =SUMIFS('[2]1.1地产销售计划表'!X:X,'[2]1.1地产销售计划表'!B:B,"海沧中心璞盛项目（一期）",'[2]1.1地产销售计划表'!G:G,"商业",'[2]1.1地产销售计划表'!H:H,"签约(元）")/100000000 -> 0 | U10: =SUMIFS('[2]1.1地产销售计划表'!X:X,'[2]1.1地产销售计划表'!B:B,"海沧中心璞盛项目（二期）",'[2]1.1地产销售计划表'!G:G,"商业",'[2]1.1地产销售计划表'!H:H,"签约(元）")/100000000 -> 0 | V10: =SUM(W10:X10) -> 0 | W10: =SUMIFS('[2]1.1地产销售计划表'!Y:Y,'[2]1.1地产销售计划表'!B:B,"海沧中心璞盛项目（一期）",'[2]1.1地产销售计划表'!G:G,"商业",'[2]1.1地产销售计划表'!H:H,"签约(元）")/100000000 -> 0 | X10: =SUMIFS('[2]1.1地产销售计划表'!Y:Y,'[2]1.1地产销售计划表'!B:B,"海沧中心璞盛项目（二期）",'[2]1.1地产销售计划表'!G:G,"商业",'[2]1.1地产销售计划表'!H:H,"签约(元）")/100000000 -> 0 | Y10: =SUM(Z10:AA10) -> 0 | Z10: =SUMIFS('[2]1.1地产销售计划表'!Z:Z,'[2]1.1地产销售计划表'!B:B,"海沧中心璞盛项目（一期）",'[2]1.1地产销售计划表'!G:G,"商业",'[2]1.1地产销售计划表'!H:H,"签约(元）")/100000000 -> 0 | AA10: =SUMIFS('[2]1.1地产销售计划表'!Z:Z,'[2]1.1地产销售计划表'!B:B,"海沧中心璞盛项目（二期）",'[2]1.1地产销售计划表'!G:G,"商业",'[2]1.1地产销售计划表'!H:H,"签约(元）")/100000000 -> 0 | AB10: =SUM(AC10:AD10) -> 0.710247 | AC10: =SUMIFS('[2]1.1地产销售计划表'!AA:AA,'[2]1.1地产销售计划表'!B:B,"海沧中心璞盛项目（一期）",'[2]1.1地产销售计划表'!G:G,"商业",'[2]1.1地产销售计划表'!H:H,"签约(元）")/100000000 -> 0.628269 | AD10: =SUMIFS('[2]1.1地产销售计划表'!AA:AA,'[2]1.1地产销售计划表'!B:B,"海沧中心璞盛项目（二期）",'[2]1.1地产销售计划表'!G:G,"商业",'[2]1.1地产销售计划表'!H:H,"签约(元）")/100000000 -> 0.081978 | AE10: =SUM(AF10:AG10) -> 0 | AF10: =SUMIFS('[2]1.1地产销售计划表'!AB:AB,'[2]1.1地产销售计划表'!B:B,"海沧中心璞盛项目（一期）",'[2]1.1地产销售计划表'!G:G,"商业",'[2]1.1地产销售计划表'!H:H,"签约(元）")/100000000 -> 0 | AG10: =SUMIFS('[2]1.1地产销售计划表'!AB:AB,'[2]1.1地产销售计划表'!B:B,"海沧中心璞盛项目（二期）",'[2]1.1地产销售计划表'!G:G,"商业",'[2]1.1地产销售计划表'!H:H,"签约(元）")/100000000 -> 0
C11: 车位 | D11: =SUM(E11:F11) -> 1.751 | E11: =SUM(H11,Q11,T11,W11,Z11,AC11,AF11) -> 1.4932 | F11: =SUM(I11,R11,U11,X11,AA11,AD11,AG11) -> 0.2578 | G11: =SUM(H11:I11) -> 0.2841 | H11: =(SUMIFS('[2]1.1地产销售计划表'!N:N,'[2]1.1地产销售计划表'!B:B,"海沧中心璞盛项目（一期）",'[2]1.1地产销售计划表'!G:G,"车位",'[2]1.1地产销售计划表'!H:H,"签约(元）")+SUMIFS('[2]1.1地产销售计划表'!V:V,'[2]1.1地产销售计划表'!B:B,"海沧中心璞盛项目（一期）",'[2]1.1地产销售计划表'!G:G,"车位",'[2]1.1地产销售计划表'!H:H,"签约(元）"))/100000000 -> 0.2163 | I11: =(SUMIFS('[2]1.1地产销售计划表'!N:N,'[2]1.1地产销售计划表'!B:B,"海沧中心璞盛项目（二期）",'[2]1.1地产销售计划表'!G:G,"车位",'[2]1.1地产销售计划表'!H:H,"签约(元）")+SUMIFS('[2]1.1地产销售计划表'!V:V,'[2]1.1地产销售计划表'!B:B,"海沧中心璞盛项目（二期）",'[2]1.1地产销售计划表'!G:G,"车位",'[2]1.1地产销售计划表'!H:H,"签约(元）"))/100000000 -> 0.0678 | P11: =SUM(Q11:R11) -> 0.0608 | Q11: =SUMIFS('[2]1.1地产销售计划表'!W:W,'[2]1.1地产销售计划表'!B:B,"海沧中心璞盛项目（一期）",'[2]1.1地产销售计划表'!G:G,"车位",'[2]1.1地产销售计划表'!H:H,"签约(元）")/100000000 -> 0.0608 | R11: =SUMIFS('[2]1.1地产销售计划表'!W:W,'[2]1.1地产销售计划表'!B:B,"海沧中心璞盛项目（二期）",'[2]1.1地产销售计划表'!G:G,"车位",'[2]1.1地产销售计划表'!H:H,"签约(元）")/100000000 -> 0 | S11: =SUM(T11:U11) -> 0.391689 | T11: =SUMIFS('[2]1.1地产销售计划表'!X:X,'[2]1.1地产销售计划表'!B:B,"海沧中心璞盛项目（一期）",'[2]1.1地产销售计划表'!G:G,"车位",'[2]1.1地产销售计划表'!H:H,"签约(元）")/100000000 -> 0.278389 | U11: =SUMIFS('[2]1.1地产销售计划表'!X:X,'[2]1.1地产销售计划表'!B:B,"海沧中心璞盛项目（二期）",'[2]1.1地产销售计划表'!G:G,"车位",'[2]1.1地产销售计划表'!H:H,"签约(元）")/100000000 -> 0.1133 | V11: =SUM(W11:X11) -> 0.442411 | W11: =SUMIFS('[2]1.1地产销售计划表'!Y:Y,'[2]1.1地产销售计划表'!B:B,"海沧中心璞盛项目（一期）",'[2]1.1地产销售计划表'!G:G,"车位",'[2]1.1地产销售计划表'!H:H,"签约(元）")/100000000 -> 0.442411 | X11: =SUMIFS('[2]1.1地产销售计划表'!Y:Y,'[2]1.1地产销售计划表'!B:B,"海沧中心璞盛项目（二期）",'[2]1.1地产销售计划表'!G:G,"车位",'[2]1.1地产销售计划表'!H:H,"签约(元）")/100000000 -> 0 | Y11: =SUM(Z11:AA11) -> 0 | Z11: =SUMIFS('[2]1.1地产销售计划表'!Z:Z,'[2]1.1地产销售计划表'!B:B,"海沧中心璞盛项目（一期）",'[2]1.1地产销售计划表'!G:G,"车位",'[2]1.1地产销售计划表'!H:H,"签约(元）")/100000000 -> 0 | AA11: =SUMIFS('[2]1.1地产销售计划表'!Z:Z,'[2]1.1地产销售计划表'!B:B,"海沧中心璞盛项目（二期）",'[2]1.1地产销售计划表'!G:G,"车位",'[2]1.1地产销售计划表'!H:H,"签约(元）")/100000000 -> 0 | AB11: =SUM(AC11:AD11) -> 0.572 | AC11: =+AC21*AC26/10000 -> 0.4953 | AD11: =+AD21*AD26/10000 -> 0.0767 | AE11: =SUM(AF11:AG11) -> 0 | AF11: =SUMIFS('[2]1.1地产销售计划表'!AB:AB,'[2]1.1地产销售计划表'!B:B,"海沧中心璞盛项目（一期）",'[2]1.1地产销售计划表'!G:G,"车位",'[2]1.1地产销售计划表'!H:H,"签约(元）")/100000000 -> 0 | AG11: =SUMIFS('[2]1.1地产销售计划表'!AB:AB,'[2]1.1地产销售计划表'!B:B,"海沧中心璞盛项目（二期）",'[2]1.1地产销售计划表'!G:G,"车位",'[2]1.1地产销售计划表'!H:H,"签约(元）")/100000000 -> 0
A12: 面积 | C12: 住宅 | D12: =SUM(E12:F12) -> 12.032753 | E12: =SUM(H12,Q12,T12,W12,Z12,AC12,AF12) -> 9.643089 | F12: =SUM(I12,R12,U12,X12,AA12,AD12,AG12) -> 2.389664 | G12: =SUM(H12:I12) -> 8.731332 | H12: =SUM(H13:H14) -> 6.595078 | I12: =SUM(I13:I14) -> 2.136254 | J12: =SUM(J13:J14) -> 0 | K12: =SUM(K13:K14) -> 0 | L12: =SUM(L13:L14) -> 0 | M12: =SUM(M13:M14) -> 0 | N12: =SUM(N13:N14) -> 0 | O12: =SUM(O13:O14) -> 0 | ... AG12: =SUM(AG13:AG14) -> 0
C13: 其中：普宅 | D13: =SUM(E13:F13) -> 9.143207 | E13: =SUM(H13,Q13,T13,W13,Z13,AC13,AF13) -> 6.753543 | F13: =SUM(I13,R13,U13,X13,AA13,AD13,AG13) -> 2.389664 | G13: =SUM(H13:I13) -> 8.731332 | H13: =(SUMIFS('[2]1.1地产销售计划表'!N:N,'[2]1.1地产销售计划表'!B:B,"海沧中心璞盛项目（一期）",'[2]1.1地产销售计划表'!G:G,"住宅-精装普宅",'[2]1.1地产销售计划表'!H:H,"面积（㎡）")+SUMIFS('[2]1.1地产销售计划表'!V:V,'[2]1.1地产销售计划表'!B:B,"海沧中心璞盛项目（一期）",'[2]1.1地产销售计划表'!G:G,"住宅-精装普宅",'[2]1.1地产销售计划表'!H:H,"面积（㎡）"))/10000 -> 6.595078 | I13: =(SUMIFS('[2]1.1地产销售计划表'!N:N,'[2]1.1地产销售计划表'!B:B,"海沧中心璞盛项目（二期）",'[2]1.1地产销售计划表'!G:G,"住宅-精装普宅",'[2]1.1地产销售计划表'!H:H,"面积（㎡）")+SUMIFS('[2]1.1地产销售计划表'!V:V,'[2]1.1地产销售计划表'!B:B,"海沧中心璞盛项目（二期）",'[2]1.1地产销售计划表'!G:G,"住宅-精装普宅",'[2]1.1地产销售计划表'!H:H,"面积（㎡）"))/10000 -> 2.136254 | P13: =SUM(Q13:R13) -> 0.411875 | Q13: =SUMIFS('[2]1.1地产销售计划表'!W:W,'[2]1.1地产销售计划表'!B:B,"海沧中心璞盛项目（一期）",'[2]1.1地产销售计划表'!G:G,"住宅-精装普宅",'[2]1.1地产销售计划表'!H:H,"面积（㎡）")/10000 -> 0.158465 | R13: =SUMIFS('[2]1.1地产销售计划表'!W:W,'[2]1.1地产销售计划表'!B:B,"海沧中心璞盛项目（二期）",'[2]1.1地产销售计划表'!G:G,"住宅-精装普宅",'[2]1.1地产销售计划表'!H:H,"面积（㎡）")/10000 -> 0.25341 | S13: =SUM(T13:U13) -> 0 | T13: =SUMIFS('[2]1.1地产销售计划表'!X:X,'[2]1.1地产销售计划表'!B:B,"海沧中心璞盛项目（一期）",'[2]1.1地产销售计划表'!G:G,"住宅-精装普宅",'[2]1.1地产销售计划表'!H:H,"面积（㎡）")/10000 -> 0 | U13: =SUMIFS('[2]1.1地产销售计划表'!X:X,'[2]1.1地产销售计划表'!B:B,"海沧中心璞盛项目（二期）",'[2]1.1地产销售计划表'!G:G,"住宅-精装普宅",'[2]1.1地产销售计划表'!H:H,"面积（㎡）")/10000 -> 0 | V13: =SUM(W13:X13) -> 0 | W13: =SUMIFS('[2]1.1地产销售计划表'!Y:Y,'[2]1.1地产销售计划表'!B:B,"海沧中心璞盛项目（一期）",'[2]1.1地产销售计划表'!G:G,"住宅-精装普宅",'[2]1.1地产销售计划表'!H:H,"面积（㎡）")/10000 -> 0 | X13: =SUMIFS('[2]1.1地产销售计划表'!Y:Y,'[2]1.1地产销售计划表'!B:B,"海沧中心璞盛项目（二期）",'[2]1.1地产销售计划表'!G:G,"住宅-精装普宅",'[2]1.1地产销售计划表'!H:H,"面积（㎡）")/10000 -> 0 | Y13: =SUM(Z13:AA13) -> 0 | Z13: =SUMIFS('[2]1.1地产销售计划表'!Z:Z,'[2]1.1地产销售计划表'!B:B,"海沧中心璞盛项目（一期）",'[2]1.1地产销售计划表'!G:G,"住宅-精装普宅",'[2]1.1地产销售计划表'!H:H,"面积（㎡）")/10000 -> 0 | AA13: =SUMIFS('[2]1.1地产销售计划表'!Z:Z,'[2]1.1地产销售计划表'!B:B,"海沧中心璞盛项目（二期）",'[2]1.1地产销售计划表'!G:G,"住宅-精装普宅",'[2]1.1地产销售计划表'!H:H,"面积（㎡）")/10000 -> 0 | AB13: =SUM(AC13:AD13) -> 0 | AC13: =SUMIFS('[2]1.1地产销售计划表'!AA:AA,'[2]1.1地产销售计划表'!B:B,"海沧中心璞盛项目（一期）",'[2]1.1地产销售计划表'!G:G,"住宅-精装普宅",'[2]1.1地产销售计划表'!H:H,"面积（㎡）")/10000 -> 0 | AD13: =SUMIFS('[2]1.1地产销售计划表'!AA:AA,'[2]1.1地产销售计划表'!B:B,"海沧中心璞盛项目（二期）",'[2]1.1地产销售计划表'!G:G,"住宅-精装普宅",'[2]1.1地产销售计划表'!H:H,"面积（㎡）")/10000 -> 0 | AE13: =SUM(AF13:AG13) -> 0 | AF13: =SUMIFS('[2]1.1地产销售计划表'!AB:AB,'[2]1.1地产销售计划表'!B:B,"海沧中心璞盛项目（一期）",'[2]1.1地产销售计划表'!G:G,"住宅-精装普宅",'[2]1.1地产销售计划表'!H:H,"面积（㎡）")/10000 -> 0 | AG13: =SUMIFS('[2]1.1地产销售计划表'!AB:AB,'[2]1.1地产销售计划表'!B:B,"海沧中心璞盛项目（二期）",'[2]1.1地产销售计划表'!G:G,"住宅-精装普宅",'[2]1.1地产销售计划表'!H:H,"面积（㎡）")/10000 -> 0
C14: 非普宅 | D14: =SUM(E14:F14) -> 2.889546 | E14: =SUM(H14,Q14,T14,W14,Z14,AC14,AF14) -> 2.889546 | F14: =SUM(I14,R14,U14,X14,AA14,AD14,AG14) -> 0 | G14: =SUM(H14:I14) -> 0 | H14: =(SUMIFS('[2]1.1地产销售计划表'!N:N,'[2]1.1地产销售计划表'!B:B,"海沧中心璞盛项目（一期）",'[2]1.1地产销售计划表'!G:G,"住宅-精装非普宅",'[2]1.1地产销售计划表'!H:H,"面积（㎡）")+SUMIFS('[2]1.1地产销售计划表'!V:V,'[2]1.1地产销售计划表'!B:B,"海沧中心璞盛项目（一期）",'[2]1.1地产销售计划表'!G:G,"住宅-精装非普宅",'[2]1.1地产销售计划表'!H:H,"面积（㎡）"))/10000 -> 0 | I14: =(SUMIFS('[2]1.1地产销售计划表'!N:N,'[2]1.1地产销售计划表'!B:B,"海沧中心璞盛项目（二期）",'[2]1.1地产销售计划表'!G:G,"住宅-精装非普宅",'[2]1.1地产销售计划表'!H:H,"面积（㎡）")+SUMIFS('[2]1.1地产销售计划表'!V:V,'[2]1.1地产销售计划表'!B:B,"海沧中心璞盛项目（二期）",'[2]1.1地产销售计划表'!G:G,"住宅-精装非普宅",'[2]1.1地产销售计划表'!H:H,"面积（㎡）"))/10000 -> 0 | P14: =SUM(Q14:R14) -> 1.7543672 | Q14: =SUMIFS('[2]1.1地产销售计划表'!W:W,'[2]1.1地产销售计划表'!B:B,"海沧中心璞盛项目（一期）",'[2]1.1地产销售计划表'!G:G,"住宅-精装非普宅",'[2]1.1地产销售计划表'!H:H,"面积（㎡）")/10000 -> 1.7543672 | R14: =SUMIFS('[2]1.1地产销售计划表'!W:W,'[2]1.1地产销售计划表'!B:B,"海沧中心璞盛项目（二期）",'[2]1.1地产销售计划表'!G:G,"住宅-精装非普宅",'[2]1.1地产销售计划表'!H:H,"面积（㎡）")/10000 -> 0 | S14: =SUM(T14:U14) -> 1.1351788 | T14: =SUMIFS('[2]1.1地产销售计划表'!X:X,'[2]1.1地产销售计划表'!B:B,"海沧中心璞盛项目（一期）",'[2]1.1地产销售计划表'!G:G,"住宅-精装非普宅",'[2]1.1地产销售计划表'!H:H,"面积（㎡）")/10000 -> 1.1351788 | U14: =SUMIFS('[2]1.1地产销售计划表'!X:X,'[2]1.1地产销售计划表'!B:B,"海沧中心璞盛项目（二期）",'[2]1.1地产销售计划表'!G:G,"住宅-精装非普宅",'[2]1.1地产销售计划表'!H:H,"面积（㎡）")/10000 -> 0 | V14: =SUM(W14:X14) -> 0 | W14: =SUMIFS('[2]1.1地产销售计划表'!Y:Y,'[2]1.1地产销售计划表'!B:B,"海沧中心璞盛项目（一期）",'[2]1.1地产销售计划表'!G:G,"住宅-精装非普宅",'[2]1.1地产销售计划表'!H:H,"面积（㎡）")/10000 -> 0 | X14: =SUMIFS('[2]1.1地产销售计划表'!Y:Y,'[2]1.1地产销售计划表'!B:B,"海沧中心璞盛项目（二期）",'[2]1.1地产销售计划表'!G:G,"住宅-精装非普宅",'[2]1.1地产销售计划表'!H:H,"面积（㎡）")/10000 -> 0 | Y14: =SUM(Z14:AA14) -> 0 | Z14: =SUMIFS('[2]1.1地产销售计划表'!Z:Z,'[2]1.1地产销售计划表'!B:B,"海沧中心璞盛项目（一期）",'[2]1.1地产销售计划表'!G:G,"住宅-精装非普宅",'[2]1.1地产销售计划表'!H:H,"面积（㎡）")/10000 -> 0 | AA14: =SUMIFS('[2]1.1地产销售计划表'!Z:Z,'[2]1.1地产销售计划表'!B:B,"海沧中心璞盛项目（二期）",'[2]1.1地产销售计划表'!G:G,"住宅-精装非普宅",'[2]1.1地产销售计划表'!H:H,"面积（㎡）")/10000 -> 0 | AB14: =SUM(AC14:AD14) -> 0 | AC14: =SUMIFS('[2]1.1地产销售计划表'!AA:AA,'[2]1.1地产销售计划表'!B:B,"海沧中心璞盛项目（一期）",'[2]1.1地产销售计划表'!G:G,"住宅-精装非普宅",'[2]1.1地产销售计划表'!H:H,"面积（㎡）")/10000 -> 0 | AD14: =SUMIFS('[2]1.1地产销售计划表'!AA:AA,'[2]1.1地产销售计划表'!B:B,"海沧中心璞盛项目（二期）",'[2]1.1地产销售计划表'!G:G,"住宅-精装非普宅",'[2]1.1地产销售计划表'!H:H,"面积（㎡）")/10000 -> 0 | AE14: =SUM(AF14:AG14) -> 0 | AF14: =SUMIFS('[2]1.1地产销售计划表'!AB:AB,'[2]1.1地产销售计划表'!B:B,"海沧中心璞盛项目（一期）",'[2]1.1地产销售计划表'!G:G,"住宅-精装非普宅",'[2]1.1地产销售计划表'!H:H,"面积（㎡）")/10000 -> 0 | AG14: =SUMIFS('[2]1.1地产销售计划表'!AB:AB,'[2]1.1地产销售计划表'!B:B,"海沧中心璞盛项目（二期）",'[2]1.1地产销售计划表'!G:G,"住宅-精装非普宅",'[2]1.1地产销售计划表'!H:H,"面积（㎡）")/10000 -> 0
C15: 商业 | D15: =SUM(E15:F15) -> 0.236749 | E15: =SUM(H15,Q15,T15,W15,Z15,AC15,AF15) -> 0.209423 | F15: =SUM(I15,R15,U15,X15,AA15,AD15,AG15) -> 0.027326 | G15: =SUM(H15:I15) -> 0 | H15: =(SUMIFS('[2]1.1地产销售计划表'!N:N,'[2]1.1地产销售计划表'!B:B,"海沧中心璞盛项目（一期）",'[2]1.1地产销售计划表'!G:G,"商业",'[2]1.1地产销售计划表'!H:H,"面积（㎡）")+SUMIFS('[2]1.1地产销售计划表'!V:V,'[2]1.1地产销售计划表'!B:B,"海沧中心璞盛项目（一期）",'[2]1.1地产销售计划表'!G:G,"商业",'[2]1.1地产销售计划表'!H:H,"面积（㎡）"))/10000 -> 0 | I15: =(SUMIFS('[2]1.1地产销售计划表'!N:N,'[2]1.1地产销售计划表'!B:B,"海沧中心璞盛项目（二期）",'[2]1.1地产销售计划表'!G:G,"商业",'[2]1.1地产销售计划表'!H:H,"面积（㎡）")+SUMIFS('[2]1.1地产销售计划表'!V:V,'[2]1.1地产销售计划表'!B:B,"海沧中心璞盛项目（二期）",'[2]1.1地产销售计划表'!G:G,"商业",'[2]1.1地产销售计划表'!H:H,"面积（㎡）"))/10000 -> 0 | P15: =SUM(Q15:R15) -> 0 | Q15: =SUMIFS('[2]1.1地产销售计划表'!W:W,'[2]1.1地产销售计划表'!B:B,"海沧中心璞盛项目（一期）",'[2]1.1地产销售计划表'!G:G,"商业",'[2]1.1地产销售计划表'!H:H,"面积（㎡）")/10000 -> 0 | R15: =SUMIFS('[2]1.1地产销售计划表'!W:W,'[2]1.1地产销售计划表'!B:B,"海沧中心璞盛项目（二期）",'[2]1.1地产销售计划表'!G:G,"商业",'[2]1.1地产销售计划表'!H:H,"面积（㎡）")/10000 -> 0 | S15: =SUM(T15:U15) -> 0 | T15: =SUMIFS('[2]1.1地产销售计划表'!X:X,'[2]1.1地产销售计划表'!B:B,"海沧中心璞盛项目（一期）",'[2]1.1地产销售计划表'!G:G,"商业",'[2]1.1地产销售计划表'!H:H,"面积（㎡）")/10000 -> 0 | U15: =SUMIFS('[2]1.1地产销售计划表'!X:X,'[2]1.1地产销售计划表'!B:B,"海沧中心璞盛项目（二期）",'[2]1.1地产销售计划表'!G:G,"商业",'[2]1.1地产销售计划表'!H:H,"面积（㎡）")/10000 -> 0 | V15: =SUM(W15:X15) -> 0 | W15: =SUMIFS('[2]1.1地产销售计划表'!Y:Y,'[2]1.1地产销售计划表'!B:B,"海沧中心璞盛项目（一期）",'[2]1.1地产销售计划表'!G:G,"商业",'[2]1.1地产销售计划表'!H:H,"面积（㎡）")/10000 -> 0 | X15: =SUMIFS('[2]1.1地产销售计划表'!Y:Y,'[2]1.1地产销售计划表'!B:B,"海沧中心璞盛项目（二期）",'[2]1.1地产销售计划表'!G:G,"商业",'[2]1.1地产销售计划表'!H:H,"面积（㎡）")/10000 -> 0 | Y15: =SUM(Z15:AA15) -> 0 | Z15: =SUMIFS('[2]1.1地产销售计划表'!Z:Z,'[2]1.1地产销售计划表'!B:B,"海沧中心璞盛项目（一期）",'[2]1.1地产销售计划表'!G:G,"商业",'[2]1.1地产销售计划表'!H:H,"面积（㎡）")/10000 -> 0 | AA15: =SUMIFS('[2]1.1地产销售计划表'!Z:Z,'[2]1.1地产销售计划表'!B:B,"海沧中心璞盛项目（二期）",'[2]1.1地产销售计划表'!G:G,"商业",'[2]1.1地产销售计划表'!H:H,"面积（㎡）")/10000 -> 0 | AB15: =SUM(AC15:AD15) -> 0.236749 | AC15: =SUMIFS('[2]1.1地产销售计划表'!AA:AA,'[2]1.1地产销售计划表'!B:B,"海沧中心璞盛项目（一期）",'[2]1.1地产销售计划表'!G:G,"商业",'[2]1.1地产销售计划表'!H:H,"面积（㎡）")/10000 -> 0.209423 | AD15: =SUMIFS('[2]1.1地产销售计划表'!AA:AA,'[2]1.1地产销售计划表'!B:B,"海沧中心璞盛项目（二期）",'[2]1.1地产销售计划表'!G:G,"商业",'[2]1.1地产销售计划表'!H:H,"面积（㎡）")/10000 -> 0.027326 | AE15: =SUM(AF15:AG15) -> 0 | AF15: =SUMIFS('[2]1.1地产销售计划表'!AB:AB,'[2]1.1地产销售计划表'!B:B,"海沧中心璞盛项目（一期）",'[2]1.1地产销售计划表'!G:G,"商业",'[2]1.1地产销售计划表'!H:H,"面积（㎡）")/10000 -> 0 | AG15: =SUMIFS('[2]1.1地产销售计划表'!AB:AB,'[2]1.1地产销售计划表'!B:B,"海沧中心璞盛项目（二期）",'[2]1.1地产销售计划表'!G:G,"商业",'[2]1.1地产销售计划表'!H:H,"面积（㎡）")/10000 -> 0
C16: 车位 | D16: =SUM(E16:F16) -> 3.5963006 | E16: =SUM(H16,Q16,T16,W16,Z16,AC16,AF16) -> 3.033058 | F16: =SUM(I16,R16,U16,X16,AA16,AD16,AG16) -> 0.56324258 | G16: =SUM(H16:I16) -> 0.402369 | H16: =(SUMIFS('[2]1.1地产销售计划表'!N:N,'[2]1.1地产销售计划表'!B:B,"海沧中心璞盛项目（一期）",'[2]1.1地产销售计划表'!G:G,"车位",'[2]1.1地产销售计划表'!H:H,"面积（㎡）")+SUMIFS('[2]1.1地产销售计划表'!V:V,'[2]1.1地产销售计划表'!B:B,"海沧中心璞盛项目（一期）",'[2]1.1地产销售计划表'!G:G,"车位",'[2]1.1地产销售计划表'!H:H,"面积（㎡）"))/10000 -> 0.312405 | I16: =(SUMIFS('[2]1.1地产销售计划表'!N:N,'[2]1.1地产销售计划表'!B:B,"海沧中心璞盛项目（二期）",'[2]1.1地产销售计划表'!G:G,"车位",'[2]1.1地产销售计划表'!H:H,"面积（㎡）")+SUMIFS('[2]1.1地产销售计划表'!V:V,'[2]1.1地产销售计划表'!B:B,"海沧中心璞盛项目（二期）",'[2]1.1地产销售计划表'!G:G,"车位",'[2]1.1地产销售计划表'!H:H,"面积（㎡）"))/10000 -> 0.089964 | P16: =SUM(Q16:R16) -> 0.122094 | Q16: =SUMIFS('[2]1.1地产销售计划表'!W:W,'[2]1.1地产销售计划表'!B:B,"海沧中心璞盛项目（一期）",'[2]1.1地产销售计划表'!G:G,"车位",'[2]1.1地产销售计划表'!H:H,"面积（㎡）")/10000 -> 0.122094 | R16: =SUMIFS('[2]1.1地产销售计划表'!W:W,'[2]1.1地产销售计划表'!B:B,"海沧中心璞盛项目（二期）",'[2]1.1地产销售计划表'!G:G,"车位",'[2]1.1地产销售计划表'!H:H,"面积（㎡）")/10000 -> 0 | S16: =SUM(T16:U16) -> 0.740981 | T16: =SUMIFS('[2]1.1地产销售计划表'!X:X,'[2]1.1地产销售计划表'!B:B,"海沧中心璞盛项目（一期）",'[2]1.1地产销售计划表'!G:G,"车位",'[2]1.1地产销售计划表'!H:H,"面积（㎡）")/10000 -> 0.536571 | U16: =SUMIFS('[2]1.1地产销售计划表'!X:X,'[2]1.1地产销售计划表'!B:B,"海沧中心璞盛项目（二期）",'[2]1.1地产销售计划表'!G:G,"车位",'[2]1.1地产销售计划表'!H:H,"面积（㎡）")/10000 -> 0.20441 | V16: =SUM(W16:X16) -> 0.862566 | W16: =SUMIFS('[2]1.1地产销售计划表'!Y:Y,'[2]1.1地产销售计划表'!B:B,"海沧中心璞盛项目（一期）",'[2]1.1地产销售计划表'!G:G,"车位",'[2]1.1地产销售计划表'!H:H,"面积（㎡）")/10000 -> 0.862566 | X16: =SUMIFS('[2]1.1地产销售计划表'!Y:Y,'[2]1.1地产销售计划表'!B:B,"海沧中心璞盛项目（二期）",'[2]1.1地产销售计划表'!G:G,"车位",'[2]1.1地产销售计划表'!H:H,"面积（㎡）")/10000 -> 0 | Y16: =SUM(Z16:AA16) -> 0 | Z16: =SUMIFS('[2]1.1地产销售计划表'!Z:Z,'[2]1.1地产销售计划表'!B:B,"海沧中心璞盛项目（一期）",'[2]1.1地产销售计划表'!G:G,"车位",'[2]1.1地产销售计划表'!H:H,"面积（㎡）")/10000 -> 0 | AA16: =SUMIFS('[2]1.1地产销售计划表'!Z:Z,'[2]1.1地产销售计划表'!B:B,"海沧中心璞盛项目（二期）",'[2]1.1地产销售计划表'!G:G,"车位",'[2]1.1地产销售计划表'!H:H,"面积（㎡）")/10000 -> 0 | AB16: =SUM(AC16:AD16) -> 1.4682906 | AC16: =+AC21*N61/10000 -> 1.199422 | AD16: =+AD21*N67/10000 -> 0.26886858 | AE16: =SUM(AF16:AG16) -> 0 | AF16: =SUMIFS('[2]1.1地产销售计划表'!AB:AB,'[2]1.1地产销售计划表'!B:B,"海沧中心璞盛项目（一期）",'[2]1.1地产销售计划表'!G:G,"车位",'[2]1.1地产销售计划表'!H:H,"面积（㎡）")/10000 -> 0 | AG16: =SUMIFS('[2]1.1地产销售计划表'!AB:AB,'[2]1.1地产销售计划表'!B:B,"海沧中心璞盛项目（二期）",'[2]1.1地产销售计划表'!G:G,"车位",'[2]1.1地产销售计划表'!H:H,"面积（㎡）")/10000 -> 0
A17: 套数 | C17: 住宅 | D17: =SUM(E17:F17) -> 1055 | E17: =SUM(H17,Q17,T17,W17,Z17,AC17,AF17) -> 828 | F17: =SUM(I17,R17,U17,X17,AA17,AD17,AG17) -> 227 | G17: =SUM(H17:I17) -> 856 | H17: =SUM(H18:H19) -> 648 | I17: =SUM(I18:I19) -> 208 | J17: =SUM(J18:J19) -> 0 | K17: =SUM(K18:K19) -> 0 | L17: =SUM(L18:L19) -> 0 | M17: =SUM(M18:M19) -> 0 | N17: =SUM(N18:N19) -> 0 | O17: =SUM(O18:O19) -> 0 | ... AG17: =SUM(AG18:AG19) -> 0
C18: 其中：普宅 | D18: =SUM(E18:F18) -> 887 | E18: =SUM(H18,Q18,T18,W18,Z18,AC18,AF18) -> 660 | F18: =SUM(I18,R18,U18,X18,AA18,AD18,AG18) -> 227 | G18: =SUM(H18:I18) -> 856 | H18: =SUMIFS('[2]1.1地产销售计划表'!N:N,'[2]1.1地产销售计划表'!B:B,"海沧中心璞盛项目（一期）",'[2]1.1地产销售计划表'!G:G,"住宅-精装普宅",'[2]1.1地产销售计划表'!H:H,"套数（套）")+SUMIFS('[2]1.1地产销售计划表'!V:V,'[2]1.1地产销售计划表'!B:B,"海沧中心璞盛项目（一期）",'[2]1.1地产销售计划表'!G:G,"住宅-精装普宅",'[2]1.1地产销售计划表'!H:H,"套数（套）") -> 648 | I18: =SUMIFS('[2]1.1地产销售计划表'!N:N,'[2]1.1地产销售计划表'!B:B,"海沧中心璞盛项目（二期）",'[2]1.1地产销售计划表'!G:G,"住宅-精装普宅",'[2]1.1地产销售计划表'!H:H,"套数（套）")+SUMIFS('[2]1.1地产销售计划表'!V:V,'[2]1.1地产销售计划表'!B:B,"海沧中心璞盛项目（二期）",'[2]1.1地产销售计划表'!G:G,"住宅-精装普宅",'[2]1.1地产销售计划表'!H:H,"套数（套）") -> 208 | P18: =SUM(Q18:R18) -> 31 | Q18: =SUMIFS('[2]1.1地产销售计划表'!W:W,'[2]1.1地产销售计划表'!B:B,"海沧中心璞盛项目（一期）",'[2]1.1地产销售计划表'!G:G,"住宅-精装普宅",'[2]1.1地产销售计划表'!H:H,"套数（套）") -> 12 | R18: =SUMIFS('[2]1.1地产销售计划表'!W:W,'[2]1.1地产销售计划表'!B:B,"海沧中心璞盛项目（二期）",'[2]1.1地产销售计划表'!G:G,"住宅-精装普宅",'[2]1.1地产销售计划表'!H:H,"套数（套）") -> 19 | S18: =SUM(T18:U18) -> 0 | T18: =SUMIFS('[2]1.1地产销售计划表'!X:X,'[2]1.1地产销售计划表'!B:B,"海沧中心璞盛项目（一期）",'[2]1.1地产销售计划表'!G:G,"住宅-精装普宅",'[2]1.1地产销售计划表'!H:H,"套数（套）") -> 0 | U18: =SUMIFS('[2]1.1地产销售计划表'!X:X,'[2]1.1地产销售计划表'!B:B,"海沧中心璞盛项目（二期）",'[2]1.1地产销售计划表'!G:G,"住宅-精装普宅",'[2]1.1地产销售计划表'!H:H,"套数（套）") -> 0 | V18: =SUM(W18:X18) -> 0 | W18: =SUMIFS('[2]1.1地产销售计划表'!Y:Y,'[2]1.1地产销售计划表'!B:B,"海沧中心璞盛项目（一期）",'[2]1.1地产销售计划表'!G:G,"住宅-精装普宅",'[2]1.1地产销售计划表'!H:H,"套数（套）") -> 0 | X18: =SUMIFS('[2]1.1地产销售计划表'!Y:Y,'[2]1.1地产销售计划表'!B:B,"海沧中心璞盛项目（二期）",'[2]1.1地产销售计划表'!G:G,"住宅-精装普宅",'[2]1.1地产销售计划表'!H:H,"套数（套）") -> 0 | Y18: =SUM(Z18:AA18) -> 0 | Z18: =SUMIFS('[2]1.1地产销售计划表'!Z:Z,'[2]1.1地产销售计划表'!B:B,"海沧中心璞盛项目（一期）",'[2]1.1地产销售计划表'!G:G,"住宅-精装普宅",'[2]1.1地产销售计划表'!H:H,"套数（套）") -> 0 | AA18: =SUMIFS('[2]1.1地产销售计划表'!Z:Z,'[2]1.1地产销售计划表'!B:B,"海沧中心璞盛项目（二期）",'[2]1.1地产销售计划表'!G:G,"住宅-精装普宅",'[2]1.1地产销售计划表'!H:H,"套数（套）") -> 0 | AB18: =SUM(AC18:AD18) -> 0 | AC18: =SUMIFS('[2]1.1地产销售计划表'!AA:AA,'[2]1.1地产销售计划表'!B:B,"海沧中心璞盛项目（一期）",'[2]1.1地产销售计划表'!G:G,"住宅-精装普宅",'[2]1.1地产销售计划表'!H:H,"套数（套）") -> 0 | AD18: =SUMIFS('[2]1.1地产销售计划表'!AA:AA,'[2]1.1地产销售计划表'!B:B,"海沧中心璞盛项目（二期）",'[2]1.1地产销售计划表'!G:G,"住宅-精装普宅",'[2]1.1地产销售计划表'!H:H,"套数（套）") -> 0 | AE18: =SUM(AF18:AG18) -> 0 | AF18: =SUMIFS('[2]1.1地产销售计划表'!AB:AB,'[2]1.1地产销售计划表'!B:B,"海沧中心璞盛项目（一期）",'[2]1.1地产销售计划表'!G:G,"住宅-精装普宅",'[2]1.1地产销售计划表'!H:H,"套数（套）") -> 0 | AG18: =SUMIFS('[2]1.1地产销售计划表'!AB:AB,'[2]1.1地产销售计划表'!B:B,"海沧中心璞盛项目（二期）",'[2]1.1地产销售计划表'!G:G,"住宅-精装普宅",'[2]1.1地产销售计划表'!H:H,"套数（套）") -> 0
C19: 非普宅 | D19: =SUM(E19:F19) -> 168 | E19: =SUM(H19,Q19,T19,W19,Z19,AC19,AF19) -> 168 | F19: =SUM(I19,R19,U19,X19,AA19,AD19,AG19) -> 0 | G19: =SUM(H19:I19) -> 0 | H19: =SUMIFS('[2]1.1地产销售计划表'!N:N,'[2]1.1地产销售计划表'!B:B,"海沧中心璞盛项目（一期）",'[2]1.1地产销售计划表'!G:G,"住宅-精装非普宅",'[2]1.1地产销售计划表'!H:H,"套数（套）")+SUMIFS('[2]1.1地产销售计划表'!V:V,'[2]1.1地产销售计划表'!B:B,"海沧中心璞盛项目（一期）",'[2]1.1地产销售计划表'!G:G,"住宅-精装非普宅",'[2]1.1地产销售计划表'!H:H,"套数（套）") -> 0 | I19: =SUMIFS('[2]1.1地产销售计划表'!N:N,'[2]1.1地产销售计划表'!B:B,"海沧中心璞盛项目（二期）",'[2]1.1地产销售计划表'!G:G,"住宅-精装非普宅",'[2]1.1地产销售计划表'!H:H,"套数（套）")+SUMIFS('[2]1.1地产销售计划表'!V:V,'[2]1.1地产销售计划表'!B:B,"海沧中心璞盛项目（二期）",'[2]1.1地产销售计划表'!G:G,"住宅-精装非普宅",'[2]1.1地产销售计划表'!H:H,"套数（套）") -> 0 | P19: =SUM(Q19:R19) -> 102 | Q19: =SUMIFS('[2]1.1地产销售计划表'!W:W,'[2]1.1地产销售计划表'!B:B,"海沧中心璞盛项目（一期）",'[2]1.1地产销售计划表'!G:G,"住宅-精装非普宅",'[2]1.1地产销售计划表'!H:H,"套数（套）") -> 102 | R19: =SUMIFS('[2]1.1地产销售计划表'!W:W,'[2]1.1地产销售计划表'!B:B,"海沧中心璞盛项目（二期）",'[2]1.1地产销售计划表'!G:G,"住宅-精装非普宅",'[2]1.1地产销售计划表'!H:H,"套数（套）") -> 0 | S19: =SUM(T19:U19) -> 66 | T19: =SUMIFS('[2]1.1地产销售计划表'!X:X,'[2]1.1地产销售计划表'!B:B,"海沧中心璞盛项目（一期）",'[2]1.1地产销售计划表'!G:G,"住宅-精装非普宅",'[2]1.1地产销售计划表'!H:H,"套数（套）") -> 66 | U19: =SUMIFS('[2]1.1地产销售计划表'!X:X,'[2]1.1地产销售计划表'!B:B,"海沧中心璞盛项目（二期）",'[2]1.1地产销售计划表'!G:G,"住宅-精装非普宅",'[2]1.1地产销售计划表'!H:H,"套数（套）") -> 0 | V19: =SUM(W19:X19) -> 0 | W19: =SUMIFS('[2]1.1地产销售计划表'!Y:Y,'[2]1.1地产销售计划表'!B:B,"海沧中心璞盛项目（一期）",'[2]1.1地产销售计划表'!G:G,"住宅-精装非普宅",'[2]1.1地产销售计划表'!H:H,"套数（套）") -> 0 | X19: =SUMIFS('[2]1.1地产销售计划表'!Y:Y,'[2]1.1地产销售计划表'!B:B,"海沧中心璞盛项目（二期）",'[2]1.1地产销售计划表'!G:G,"住宅-精装非普宅",'[2]1.1地产销售计划表'!H:H,"套数（套）") -> 0 | Y19: =SUM(Z19:AA19) -> 0 | Z19: =SUMIFS('[2]1.1地产销售计划表'!Z:Z,'[2]1.1地产销售计划表'!B:B,"海沧中心璞盛项目（一期）",'[2]1.1地产销售计划表'!G:G,"住宅-精装非普宅",'[2]1.1地产销售计划表'!H:H,"套数（套）") -> 0 | AA19: =SUMIFS('[2]1.1地产销售计划表'!Z:Z,'[2]1.1地产销售计划表'!B:B,"海沧中心璞盛项目（二期）",'[2]1.1地产销售计划表'!G:G,"住宅-精装非普宅",'[2]1.1地产销售计划表'!H:H,"套数（套）") -> 0 | AB19: =SUM(AC19:AD19) -> 0 | AC19: =SUMIFS('[2]1.1地产销售计划表'!AA:AA,'[2]1.1地产销售计划表'!B:B,"海沧中心璞盛项目（一期）",'[2]1.1地产销售计划表'!G:G,"住宅-精装非普宅",'[2]1.1地产销售计划表'!H:H,"套数（套）") -> 0 | AD19: =SUMIFS('[2]1.1地产销售计划表'!AA:AA,'[2]1.1地产销售计划表'!B:B,"海沧中心璞盛项目（二期）",'[2]1.1地产销售计划表'!G:G,"住宅-精装非普宅",'[2]1.1地产销售计划表'!H:H,"套数（套）") -> 0 | AE19: =SUM(AF19:AG19) -> 0 | AF19: =SUMIFS('[2]1.1地产销售计划表'!AB:AB,'[2]1.1地产销售计划表'!B:B,"海沧中心璞盛项目（一期）",'[2]1.1地产销售计划表'!G:G,"住宅-精装非普宅",'[2]1.1地产销售计划表'!H:H,"套数（套）") -> 0 | AG19: =SUMIFS('[2]1.1地产销售计划表'!AB:AB,'[2]1.1地产销售计划表'!B:B,"海沧中心璞盛项目（二期）",'[2]1.1地产销售计划表'!G:G,"住宅-精装非普宅",'[2]1.1地产销售计划表'!H:H,"套数（套）") -> 0
C20: 商业 | D20: =SUM(E20:F20) -> 51 | E20: =SUM(H20,Q20,T20,W20,Z20,AC20,AF20) -> 44 | F20: =SUM(I20,R20,U20,X20,AA20,AD20,AG20) -> 7 | G20: =SUM(H20:I20) -> 0 | H20: =SUMIFS('[2]1.1地产销售计划表'!N:N,'[2]1.1地产销售计划表'!B:B,"海沧中心璞盛项目（一期）",'[2]1.1地产销售计划表'!G:G,"商业",'[2]1.1地产销售计划表'!H:H,"套数（套）")+SUMIFS('[2]1.1地产销售计划表'!V:V,'[2]1.1地产销售计划表'!B:B,"海沧中心璞盛项目（一期）",'[2]1.1地产销售计划表'!G:G,"商业",'[2]1.1地产销售计划表'!H:H,"套数（套）") -> 0 | I20: =SUMIFS('[2]1.1地产销售计划表'!N:N,'[2]1.1地产销售计划表'!B:B,"海沧中心璞盛项目（二期）",'[2]1.1地产销售计划表'!G:G,"商业",'[2]1.1地产销售计划表'!H:H,"套数（套）")+SUMIFS('[2]1.1地产销售计划表'!V:V,'[2]1.1地产销售计划表'!B:B,"海沧中心璞盛项目（二期）",'[2]1.1地产销售计划表'!G:G,"商业",'[2]1.1地产销售计划表'!H:H,"套数（套）") -> 0 | P20: =SUM(Q20:R20) -> 0 | Q20: =SUMIFS('[2]1.1地产销售计划表'!W:W,'[2]1.1地产销售计划表'!B:B,"海沧中心璞盛项目（一期）",'[2]1.1地产销售计划表'!G:G,"商业",'[2]1.1地产销售计划表'!H:H,"套数（套）") -> 0 | R20: =SUMIFS('[2]1.1地产销售计划表'!W:W,'[2]1.1地产销售计划表'!B:B,"海沧中心璞盛项目（二期）",'[2]1.1地产销售计划表'!G:G,"商业",'[2]1.1地产销售计划表'!H:H,"套数（套）") -> 0 | S20: =SUM(T20:U20) -> 0 | T20: =SUMIFS('[2]1.1地产销售计划表'!X:X,'[2]1.1地产销售计划表'!B:B,"海沧中心璞盛项目（一期）",'[2]1.1地产销售计划表'!G:G,"商业",'[2]1.1地产销售计划表'!H:H,"套数（套）") -> 0 | U20: =SUMIFS('[2]1.1地产销售计划表'!X:X,'[2]1.1地产销售计划表'!B:B,"海沧中心璞盛项目（二期）",'[2]1.1地产销售计划表'!G:G,"商业",'[2]1.1地产销售计划表'!H:H,"套数（套）") -> 0 | V20: =SUM(W20:X20) -> 0 | W20: =SUMIFS('[2]1.1地产销售计划表'!Y:Y,'[2]1.1地产销售计划表'!B:B,"海沧中心璞盛项目（一期）",'[2]1.1地产销售计划表'!G:G,"商业",'[2]1.1地产销售计划表'!H:H,"套数（套）") -> 0 | X20: =SUMIFS('[2]1.1地产销售计划表'!Y:Y,'[2]1.1地产销售计划表'!B:B,"海沧中心璞盛项目（二期）",'[2]1.1地产销售计划表'!G:G,"商业",'[2]1.1地产销售计划表'!H:H,"套数（套）") -> 0 | Y20: =SUM(Z20:AA20) -> 0 | Z20: =SUMIFS('[2]1.1地产销售计划表'!Z:Z,'[2]1.1地产销售计划表'!B:B,"海沧中心璞盛项目（一期）",'[2]1.1地产销售计划表'!G:G,"商业",'[2]1.1地产销售计划表'!H:H,"套数（套）") -> 0 | AA20: =SUMIFS('[2]1.1地产销售计划表'!Z:Z,'[2]1.1地产销售计划表'!B:B,"海沧中心璞盛项目（二期）",'[2]1.1地产销售计划表'!G:G,"商业",'[2]1.1地产销售计划表'!H:H,"套数（套）") -> 0 | AB20: =SUM(AC20:AD20) -> 51 | AC20: =SUMIFS('[2]1.1地产销售计划表'!AA:AA,'[2]1.1地产销售计划表'!B:B,"海沧中心璞盛项目（一期）",'[2]1.1地产销售计划表'!G:G,"商业",'[2]1.1地产销售计划表'!H:H,"套数（套）") -> 44 | AD20: =SUMIFS('[2]1.1地产销售计划表'!AA:AA,'[2]1.1地产销售计划表'!B:B,"海沧中心璞盛项目（二期）",'[2]1.1地产销售计划表'!G:G,"商业",'[2]1.1地产销售计划表'!H:H,"套数（套）") -> 7 | AE20: =SUM(AF20:AG20) -> 0 | AF20: =SUMIFS('[2]1.1地产销售计划表'!AB:AB,'[2]1.1地产销售计划表'!B:B,"海沧中心璞盛项目（一期）",'[2]1.1地产销售计划表'!G:G,"商业",'[2]1.1地产销售计划表'!H:H,"套数（套）") -> 0 | AG20: =SUMIFS('[2]1.1地产销售计划表'!AB:AB,'[2]1.1地产销售计划表'!B:B,"海沧中心璞盛项目（二期）",'[2]1.1地产销售计划表'!G:G,"商业",'[2]1.1地产销售计划表'!H:H,"套数（套）") -> 0
C21: 车位 | D21: =SUM(E21:F21) -> 1090 | E21: =SUM(H21,Q21,T21,W21,Z21,AC21,AF21) -> 942 | F21: =SUM(I21,R21,U21,X21,AA21,AD21,AG21) -> 148 | G21: =SUM(H21:I21) -> 110 | H21: =SUMIFS('[2]1.1地产销售计划表'!N:N,'[2]1.1地产销售计划表'!B:B,"海沧中心璞盛项目（一期）",'[2]1.1地产销售计划表'!G:G,"车位",'[2]1.1地产销售计划表'!H:H,"套数（套）")+SUMIFS('[2]1.1地产销售计划表'!V:V,'[2]1.1地产销售计划表'!B:B,"海沧中心璞盛项目（一期）",'[2]1.1地产销售计划表'!G:G,"车位",'[2]1.1地产销售计划表'!H:H,"套数（套）") -> 84 | I21: =SUMIFS('[2]1.1地产销售计划表'!N:N,'[2]1.1地产销售计划表'!B:B,"海沧中心璞盛项目（二期）",'[2]1.1地产销售计划表'!G:G,"车位",'[2]1.1地产销售计划表'!H:H,"套数（套）")+SUMIFS('[2]1.1地产销售计划表'!V:V,'[2]1.1地产销售计划表'!B:B,"海沧中心璞盛项目（二期）",'[2]1.1地产销售计划表'!G:G,"车位",'[2]1.1地产销售计划表'!H:H,"套数（套）") -> 26 | P21: =SUM(Q21:R21) -> 38 | Q21: =SUMIFS('[2]1.1地产销售计划表'!W:W,'[2]1.1地产销售计划表'!B:B,"海沧中心璞盛项目（一期）",'[2]1.1地产销售计划表'!G:G,"车位",'[2]1.1地产销售计划表'!H:H,"套数（套）") -> 38 | R21: =SUMIFS('[2]1.1地产销售计划表'!W:W,'[2]1.1地产销售计划表'!B:B,"海沧中心璞盛项目（二期）",'[2]1.1地产销售计划表'!G:G,"车位",'[2]1.1地产销售计划表'!H:H,"套数（套）") -> 0 | S21: =SUM(T21:U21) -> 230 | T21: =SUMIFS('[2]1.1地产销售计划表'!X:X,'[2]1.1地产销售计划表'!B:B,"海沧中心璞盛项目（一期）",'[2]1.1地产销售计划表'!G:G,"车位",'[2]1.1地产销售计划表'!H:H,"套数（套）") -> 167 | U21: =SUMIFS('[2]1.1地产销售计划表'!X:X,'[2]1.1地产销售计划表'!B:B,"海沧中心璞盛项目（二期）",'[2]1.1地产销售计划表'!G:G,"车位",'[2]1.1地产销售计划表'!H:H,"套数（套）") -> 63 | V21: =SUM(W21:X21) -> 272 | W21: =SUMIFS('[2]1.1地产销售计划表'!Y:Y,'[2]1.1地产销售计划表'!B:B,"海沧中心璞盛项目（一期）",'[2]1.1地产销售计划表'!G:G,"车位",'[2]1.1地产销售计划表'!H:H,"套数（套）") -> 272 | X21: =SUMIFS('[2]1.1地产销售计划表'!Y:Y,'[2]1.1地产销售计划表'!B:B,"海沧中心璞盛项目（二期）",'[2]1.1地产销售计划表'!G:G,"车位",'[2]1.1地产销售计划表'!H:H,"套数（套）") -> 0 | Y21: =SUM(Z21:AA21) -> 0 | Z21: =SUMIFS('[2]1.1地产销售计划表'!Z:Z,'[2]1.1地产销售计划表'!B:B,"海沧中心璞盛项目（一期）",'[2]1.1地产销售计划表'!G:G,"车位",'[2]1.1地产销售计划表'!H:H,"套数（套）") -> 0 | AA21: =SUMIFS('[2]1.1地产销售计划表'!Z:Z,'[2]1.1地产销售计划表'!B:B,"海沧中心璞盛项目（二期）",'[2]1.1地产销售计划表'!G:G,"车位",'[2]1.1地产销售计划表'!H:H,"套数（套）") -> 0 | AB21: =SUM(AC21:AD21) -> 440 | AC21: 381 | AD21: 59 | AE21: =SUM(AF21:AG21) -> 0 | AF21: =SUMIFS('[2]1.1地产销售计划表'!AB:AB,'[2]1.1地产销售计划表'!B:B,"海沧中心璞盛项目（一期）",'[2]1.1地产销售计划表'!G:G,"车位",'[2]1.1地产销售计划表'!H:H,"套数（套）") -> 0 | AG21: =SUMIFS('[2]1.1地产销售计划表'!AB:AB,'[2]1.1地产销售计划表'!B:B,"海沧中心璞盛项目（二期）",'[2]1.1地产销售计划表'!G:G,"车位",'[2]1.1地产销售计划表'!H:H,"套数（套）") -> 0
A22: 均价 | C22: 住宅 | D22: =IFERROR(+D7/D12,0) -> 3.2933628 | E22: =IFERROR(+E7/E12,0) -> 3.2595304 | F22: =IFERROR(+F7/F12,0) -> 3.4298877 | G22: =IFERROR(+G7/G12,0) -> 3.3500315 | H22: =IFERROR(+H7/H12,0) -> 3.3195124 | I22: =IFERROR(+I7/I12,0) -> 3.4442506 | J22: =IFERROR(+J7/J12,0) -> 0 | K22: =IFERROR(+K7/K12,0) -> 0 | ... AG22: =IFERROR(+AG7/AG12,0) -> 0
C23: 其中：普宅 | D23: =IFERROR(+D8/D13,0) -> 3.3508475 | E23: =IFERROR(+E8/E13,0) -> 3.32288 | F23: =IFERROR(+F8/F13,0) -> 3.4298877 | G23: =IFERROR(+G8/G13,0) -> 3.3500315 | H23: =IFERROR(+H8/H13,0) -> 3.3195124 | I23: =IFERROR(+I8/I13,0) -> 3.4442506 | J23: =IFERROR(+J8/J13,0) -> 0 | K23: =IFERROR(+K8/K13,0) -> 0 | ... AG23: =IFERROR(+AG8/AG13,0) -> 0
C24: 非普宅 | D24: =IFERROR(+D9/D14,0) -> 3.1114677 | E24: =IFERROR(+E9/E14,0) -> 3.1114677 | F24: =IFERROR(+F9/F14,0) -> 0 | G24: =IFERROR(+G9/G14,0) -> 0 | H24: =IFERROR(+H9/H14,0) -> 0 | I24: =IFERROR(+I9/I14,0) -> 0 | J24: =IFERROR(+J9/J14,0) -> 0 | K24: =IFERROR(+K9/K14,0) -> 0 | ... AG24: =IFERROR(+AG9/AG14,0) -> 0
C25: 商业 | D25: =IFERROR(+D10/D15,0) -> 3 | E25: =IFERROR(+E10/E15,0) -> 3 | F25: =IFERROR(+F10/F15,0) -> 3 | G25: =IFERROR(+G10/G15,0) -> 0 | H25: =IFERROR(+H10/H15,0) -> 0 | I25: =IFERROR(+I10/I15,0) -> 0 | J25: =IFERROR(+J10/J15,0) -> 0 | K25: =IFERROR(+K10/K15,0) -> 0 | ... AG25: =IFERROR(+AG10/AG15,0) -> 0
C26: 车位（万元/个） | D26: =IFERROR(+D11/D21,0)*10000 -> 16.06422 | E26: =IFERROR(+E11/E21,0)*10000 -> 15.85138 | F26: =IFERROR(+F11/F21,0)*10000 -> 17.418919 | G26: =IFERROR(+G11/G21,0)*10000 -> 25.827273 | H26: =IFERROR(+H11/H21,0)*10000 -> 25.75 | I26: =IFERROR(+I11/I21,0)*10000 -> 26.076923 | J26: =IFERROR(+J11/J21,0)*10000 -> 0 | K26: =IFERROR(+K11/K21,0)*10000 -> 0 | ... AB26: =IFERROR(+AB11/AB21,0)*10000 -> 13 | AC26: 13 | AD26: =+AC26 -> 13 | AE26: =IFERROR(+AE11/AE21,0)*10000 -> 0 | AF26: =IFERROR(+AF11/AF21,0)*10000 -> 0 | AG26: =IFERROR(+AG11/AG21,0)*10000 -> 0
A28: 三、成本释放情况
A29: 动态成本对比启动会可释放： | C29: ='[3]06-项目成本支付计划'!$D$58+'[3]06-项目成本支付计划'!$D$83-[1]动态成本!F10 -> 4010
A31: 四、最新利润预测
A32: 指标 | B32: 启动会整体 | C32: 预计整体 | D32: 截至25年 | E32: 26年 | F32: 27年 | G32: 28年 | H32: 29年 | I32: 30年 | J32: 31年及以后 | K32: 预计-启动会 | M32: 当前-汇报
A33: 一、营业总收入 | C33: =SUM(D33:J33) -> 386141.91 | D33: =SUM([1]附件5.恒嘉相关!D5:E5)/10000 -> 0 | E33: =SUM(E84:E87,E90:E93)/1.09 -> 0 | F33: =SUM(F84:F87,F90:F93)/1.09 -> 351803.39 | G33: =SUM(G84:G87,G90:G93)/1.09 -> 22574.784 | H33: =SUM(H84:H87,H90:H93)/1.09 -> 0 | I33: =SUM(I84:I87,I90:I93)/1.09 -> 11763.734 | J33: =SUM(J84:J87,J90:J93)/1.09 -> 0 | M33: =+C33-[4]海沧璞盛!B44 -> 7469.8092
A34: 二、营业总成本 | C34: =SUM(D34:J34) -> 266169.48 | D34: =SUM(D35,D39,D41,D44,D45,D46) -> -371.37324 | E34: =SUM(E35,E39,E41,E44,E45,E46) -> -893.97575 | F34: =SUM(F35,F39,F41,F44,F45,F46) -> 236335.05 | G34: =SUM(G35,G39,G41,G44,G45,G46) -> 18974.119 | H34: =SUM(H35,H39,H41,H44,H45,H46) -> 831.49203 | I34: =SUM(I35,I39,I41,I44,I45,I46) -> 11294.161 | J34: =SUM(J35,J39,J41,J44,J45,J46) -> 0 | M34: =+C34-[4]海沧璞盛!B45 -> -60257.619
A35: 营业成本 | C35: =SUM(D35:J35) -> 253252.5 | D35: =SUM([1]附件5.恒嘉相关!D8:E8)/10000 -> 0 | F35: {=SUMPRODUCT(F71:F73,$L$108:$L$110)+F61*$L$111+SUMPRODUCT(F77:F79,$L$114:$L$116)+F67*$L$117} -> 226685.77 | G35: {=SUMPRODUCT(G71:G73,$L$108:$L$110)+G61*$L$111+SUMPRODUCT(G77:G79,$L$114:$L$116)+G67*$L$117} -> 15583.044 | H35: {=SUMPRODUCT(H71:H73,$L$108:$L$110)+H61*$L$111+SUMPRODUCT(H77:H79,$L$114:$L$116)+H67*$L$117} -> 0 | I35: {=SUMPRODUCT(I71:I73,$L$108:$L$110)+I61*$L$111+SUMPRODUCT(I77:I79,$L$114:$L$116)+I67*$L$117} -> 10983.688 | J35: {=SUMPRODUCT(J71:J73,$L$108:$L$110)+J61*$L$111+SUMPRODUCT(J77:J79,$L$114:$L$116)+J67*$L$117} -> 0 | M35: =+C35-[4]海沧璞盛!B46 -> -57180.178
A36: 其中：土地成本 | C36: =SUM(D36:J36) -> 0 | M36: =+C36-[4]海沧璞盛!B47 -> 0
A37: 建安成本 | C37: =SUM(D37:J37) -> 0 | M37: =+C37-[4]海沧璞盛!B48 -> 0
A38: 建设期财务费用 | C38: =SUM(D38:J38) -> 0 | M38: =+C38-[4]海沧璞盛!B49 -> 0
A39: 税金及附加 | C39: =SUM(D39:J39) -> 1632.828 | D39: =+SUM([1]附件5.恒嘉相关!D9:E9)/10000 -> 242.71709 | F39: =+F33*3%*12% -> 1266.4922 | G39: =+G33*3%*12% -> 81.269224 | H39: =+H33*3%*12% -> 0 | I39: =+I33*3%*12% -> 42.349442 | J39: =+J33*3%*12% -> 0 | M39: =+C39-[4]海沧璞盛!B50 -> 339.43386
A40: 其中：土增税 | C40: =SUM(D40:J40) -> 0 | M40: =+C40-[4]海沧璞盛!B51 -> 0
A41: 销售费用 | C41: =SUM(D41:J41) -> 14049.967 | D41: =SUM([1]附件5.恒嘉相关!D10:E10)/10000 -> 1694.2074 | E41: =+[1]附件5.恒嘉相关!C80 -> 590.45922 | F41: =SUM(F42:F43) -> 9017.9373 | G41: =SUM(G42:G43) -> 2479.2397 | H41: =SUM(H42:H43) -> 0 | I41: =SUM(I42:I43) -> 268.12369 | J41: =SUM(J42:J43) -> 0 | L41: =+C41/(C33*1.09) -> 0.033381195 | M41: =+C41-[4]海沧璞盛!B52 -> 1692.6351
A42: 其中：渠道费用 | C42: =SUM(D42:J42) -> 8801.0997 | F42: =+F33*[1]附件5.恒嘉相关!$B$112 -> 8018.4425 | G42: =+G33*[1]附件5.恒嘉相关!$B$112 -> 514.53345 | H42: =+H33*[1]附件5.恒嘉相关!$B$112 -> 0 | I42: =+I33*[1]附件5.恒嘉相关!$B$112 -> 268.12369 | J42: =+J33*[1]附件5.恒嘉相关!$B$112 -> 0 | M42: =+C42-[4]海沧璞盛!B53 -> 8801.0997
...

Sheet Sheet1
A1: 面积
A2: 结转面积明细（一期） | D2: 合计 | E2: 2026年 | F2: 2027年 | G2: 2028年 | H2: 2029年 | I2: 2030年
A3: 住宅 | B3: 精装 | C3: 普通住宅 | E3: =(SUM(H13,P13,S13)*10000-E71)*0.95 -> 0 | F3: =SUM(H13,P13,S13,V13)*10000-SUM(E71:F71) -> 0 | G3: =SUM(H13,P13,S13,V13,Y13)*10000-SUM(E71:G71) -> 0 | H3: =SUM(H13,P13,S13,V13,Y13,AB13)*10000-SUM(E71:H71) -> 0 | I3: =E13*10000-SUM(E71:I71) -> 0
A4: 住宅 | B4: 精装 | C4: 非普通住宅
A5: 商办 | B5: 毛坯 | C5: 非普通住宅
A6: 车位 | B6: 毛坯 | C6: 非普通住宅
A8: 结转面积明细（二期）
A9: 住宅 | B9: 精装 | C9: 普通住宅 | E9: =(SUM(I13,R13,U13)*10000-E77)*0.95 -> 0 | F9: =SUM(I13,R13,U13,X13)*10000-SUM(E77:F77) -> 0 | G9: =SUM(I13,R13,U13,X13,AA13)*10000-SUM(E77:G77) -> 0 | H9: =SUM(I13,R13,U13,X13,AA13,AD13)*10000-SUM(E77:H77) -> 0 | I9: =F13*10000-SUM(E77:I77) -> 0
A10: 住宅 | B10: 精装 | C10: 非普通住宅
A11: 商办 | B11: 毛坯 | C11: 非普通住宅
A12: 车位 | B12: 毛坯 | C12: 非普通住宅
